Workbook

Sheet README
A1: REVEN — ZERO-BASED COST MODEL (driver-based engine)
A2: Partner Revenue OS · companion to Zero_Based_Cost_Architecture.md · SAR · KSA/GCC-calibrated · No-Hallucination
B4: PURPOSE: A live, driver-based cost engine. Set the levers (Drivers) and unit rates (Rates); the workbook
B5: computes Cost-of-Revenue, OpEx, cost-to-serve, and blended gross margin vs the >=70% floor, then
B6: reconciles the Phase-1 zero-base to the canonical 2,000,000 SAR.
B8: EVERY LINE IS JUSTIFIED: Zero-based rule: no cost exists without a reason. Every driver, rate, cost element, package,
B9: and output on every tab carries a plain-English RATIONALE column — read it to know why the line is there.
B11: HOW TO USE: 1. Edit only BLUE cells (levers & rates). 2. Yellow = highest-leverage assumptions. 3. Black = formulas,
B12: do not overtype. 4. Read outputs on Dashboard. 5. Seeded values are an ILLUSTRATIVE post-revenue scale
B13: snapshot to demonstrate the engine — replace with your instrumented data. Pre-seed is zero-revenue (Recon).
B15: FLAG LEGEND: Blue = editable input · Black = formula · Green = headline cross-sheet pull · Yellow fill = key assumption ·
B16: Green fill = PASS · Red fill = breach/attention · 📊 = benchmark-to-validate · verify = statutory, confirm before filing.
B18: VALIDATION: Every rate is a benchmark-to-validate (quote/instrument before trusting). Nothing overrides a canonical
B19: fact; the 2,000,000 SAR round is preserved on Recon. Statutory rates per Founder Questionnaire Part 3.
B21: TABS: Drivers · Rates · CBS · CostToServe · Packages · PhaseView · Dashboard · Recon

Sheet Drivers
A1: DRIVERS — business-volume levers (edit the blue cells)
A2: Illustrative scale snapshot. Every downstream cost scales from these. Rationale = why the lever matters.
A4: Lever | B4: Value | C4: Unit | D4: Flag | E4: Rationale (plain English)
A5: PHASE TOGGLE
A6: Product phase (1=Capture, 2=Settle, 3=Orchestrate) | B6: 2 | C6: phase | D6: 🟢 | E6: Gates rails/settlement cost: none of it exists before the Settle gate, so the model switches it on only at phase >= 2.
A7: CUSTOMERS BY TIER
A8: SME (Reven Start) | B8: 100 | C8: customers | D8: 🟢 | E8: Land-wedge logos at SAR 50/mo; near-zero cost-to-serve, so this count is about expansion, not margin.
A9: SMB (Growth) | B9: 20 | C9: customers | D9: 🟢 | E9: First revenue-bearing tier; a growing channel that has outgrown spreadsheets.
A10: Mid-market | B10: 8 | C10: customers | D10: 🟢 | E10: Finance-grade buyers with material partner-attributed revenue; healthy margin.
A11: Semi-government | B11: 2 | C11: customers | D11: 🟢 | E11: Vision-2030 entities; carry a residency/sovereignty premium priced to absorb its cost.
A12: Large enterprise | B12: 3 | C12: customers | D12: 🟢 | E12: Multi-entity/high-volume ecosystems; high partner counts, priced to clear the floor including drag.
A13: Total customers | B13: =SUM(B8:B12) -> 133 | E13: Sums the tier counts — the base for every per-customer cost.
A15: AVG ACTIVE (TRANSACTING) PARTNERS PER CUSTOMER, BY TIER
A16: SME (Reven Start) | B16: 8 | C16: partners/cust | D16: 🟢 | E16: Active partners is the pricing metric AND the main cost driver; larger programs cost more to run.
A17: SMB (Growth) | B17: 40 | C17: partners/cust | D17: 🟢 | E17: Active partners is the pricing metric AND the main cost driver; larger programs cost more to run.
A18: Mid-market | B18: 120 | C18: partners/cust | D18: 🟢 | E18: Active partners is the pricing metric AND the main cost driver; larger programs cost more to run.
A19: Semi-government | B19: 300 | C19: partners/cust | D19: 🟢 | E19: Active partners is the pricing metric AND the main cost driver; larger programs cost more to run.
A20: Large enterprise | B20: 500 | C20: partners/cust | D20: 🟢 | E20: Active partners is the pricing metric AND the main cost driver; larger programs cost more to run.
A21: Total active partners | B21: =SUMPRODUCT(B8:B12,B16:B20) -> 4660 | E21: The single biggest CoR driver — most infrastructure scales with partners, not seats.
A23: THROUGHPUT & VOLUME
A24: Claims / revenue events per active partner / month | B24: 2 | C24: events | D24: 🟢 | E24: Throughput that drives inference, storage and compute — the variable heart of cost-of-revenue.
A25: → Total claims / month | B25: =B21*B24 -> 9320 | E25: =partners × claims; the total volume the platform processes each month.
A26: Payouts per active partner / month (Phase >=2) | B26: 1 | C26: payouts | D26: 🟢 | E26: Only exists in the Settle phase; drives money-movement rail cost.
A27: → Total payouts / month | B27: =IF(B6>=2,B21*B26,0) -> 4660 | E27: Forced to zero until phase >= 2 — enforces phase discipline in the cost model.
A28: Evidence storage retained (GB, monotonic) | B28: 5000 | C28: GB | D28: 🟢 | E28: The evidence store only grows; without tiering this bill compounds forever — model the ratchet.
A29: Residency (L2) tenants | B29: 3 | C29: tenants | D29: 🟢 | E29: Each in-Kingdom/dedicated tenant carries a fixed premium — the GCC wedge incumbents can't retrofit.
A30: Support tickets per NON-SME customer / month | B30: 3 | C30: tickets | D30: 🟢 | E30: Human support is real COGS; SME is excluded because it must be fully self-serve (~0 human touch).
A31: → Non-SME customers | B31: =SUM(B9:B12) -> 33 | E31: The population that generates support tickets (SME deflects to self-serve).
A32: → Total support tickets / month | B32: =B31*B30 -> 99 | E32: =non-SME customers × tickets each; the load Tier-1 support must absorb.
A33: Onboardings / month | B33: 4 | C33: onboardings | D33: 🟢 | E33: Drives implementation (services) cost, which is fenced separately from subscription margin.

Sheet Rates
A1: RATES — unit rates & should-cost baselines (edit the blue cells)
A2: 📊 benchmark-to-validate: replace with vendor quotes / instrumented actuals. Statutory = verify.
A4: A. COST-OF-REVENUE UNIT RATES (SAR) | B4: Rate | C4: Unit | D4: Flag | E4: Rationale (plain English)
A5: Cloud base per customer / month | B5: 40 | C5: per cust/mo | D5: 📊 | E5: The always-on footprint every tenant consumes even at zero activity.
A6: Cloud per active partner / month | B6: 3 | C6: per partner/mo | D6: 📊 | E6: Compute/storage scales with active partners — the dominant variable infra cost.
A7: Compute + inference per claim (capped) | B7: 0.5 | C7: per claim | D7: 📊 | E7: Each claim is processed and AI-assisted; capped so AI can never blow up COGS.
A8: Object storage (evidence) per GB / month | B8: 0.9 | C8: per GB/mo | D8: 📊 | E8: Evidence retention is monotonic; unit cost × GB is the storage bill — tier it.
A9: KYB/AML per active partner / month (amortized) | B9: 1 | C9: per partner/mo | D9: 📊 | E9: Every partner is verified once for compliance; amortized to a monthly rate here.
A10: e-signature per claim | B10: 0.3 | C10: per claim | D10: 📊 | E10: Executing claims/contracts runs through a paid third-party signing rail.
A11: Payout rail per payout (Phase >=2) | B11: 2 | C11: per payout | D11: 📊 | E11: Moving money costs per payout — but only after the Settle gate opens.
A12: ZATCA e-invoicing per customer / month | B12: 0.5 | C12: per cust/mo | D12: 📊 | E12: Saudi e-invoicing is law; a per-billed-customer integration cost.
A13: Notifications per claim | B13: 0.1 | C13: per claim | D13: 📊 | E13: Every event notifies partners/customers; small but volume-scaled.
A14: Security & compliance runtime — fixed / month | B14: 8000 | C14: SAR/mo | D14: 📊 | E14: WAF/SIEM/audit baseline; cutting it loses the enterprise/gov sale — a false economy.
A15: Residency premium per L2 tenant / month | B15: 1500 | C15: per tenant/mo | D15: 📊 | E15: Incremental cost of in-Kingdom/dedicated tenancy per sovereign tenant.
A16: Support — loaded SAR per ticket | B16: 45 | C16: per ticket | D16: 📊 | E16: Fully-loaded human cost per ticket; self-serve deflection is what keeps this small.
A18: B. CUSTOMER SUCCESS — loaded SAR per account / month, by tier
A19: SME | B19: 0 | C19: per account/mo | D19: 📊 | E19: None — SME must be self-serve; any human touch erases a year's revenue.
A20: SMB | B20: 200 | C20: per account/mo | D20: 📊 | E20: Pooled CSM; light touch to protect early retention.
A21: Mid-market | B21: 800 | C21: per account/mo | D21: 📊 | E21: Named CSM; finance/legal stakeholders need managing.
A22: Semi-government | B22: 2500 | C22: per account/mo | D22: 📊 | E22: Dedicated CSM + solution architect; procurement-heavy relationships.
A23: Large enterprise | B23: 2000 | C23: per account/mo | D23: 📊 | E23: Dedicated CSM; multi-entity coordination.
A25: C. PROFESSIONAL SERVICES (fenced < 20% of revenue)
A26: Implementation fee per onboarding (services revenue) | B26: 30000 | C26: per onboarding | D26: 📊 | E26: One-time services revenue to get a customer live; fenced so it doesn't dilute the software story.
A27: Implementation loaded delivery cost per onboarding (services COGS) | B27: 25000 | C27: per onboarding | D27: 📊 | E27: Loaded delivery cost; sits in COGS, not CAC — and should trend to SI partners over time.
A29: D. SUBSCRIPTION ACV PER CUSTOMER / YEAR, BY TIER (📊 from pricing exec summary)
A30: SME | B30: 1200 | C30: SAR/yr | D30: 📊 | E30: ~SAR 600–1,788/yr band; a frictionless micro-price wedge.
A31: SMB | B31: 100000 | C31: SAR/yr | D31: 📊 | E31: SAR 67–150K band; clears the ~SAR 95–110K high-touch floor.
A32: Mid-market | B32: 300000 | C32: SAR/yr | D32: 📊 | E32: SAR 188–450K band; finance-grade attribution buyer.
A33: Semi-government | B33: 1200000 | C33: SAR/yr | D33: 📊 | E33: SAR 600K–2.5M+; sovereignty + audit mandates, custom-quoted.
A34: Large enterprise | B34: 900000 | C34: SAR/yr | D34: 📊 | E34: SAR 560K–1.9M+; multi-entity/multi-country ecosystems.
A36: E. LABOR & OPEX (monthly)
A37: Blended statutory burden % (GOSI+EOSB+medical+levy) | B37: 0.2 | C37: of base | D37: verify | E37: Uplift on base pay for statutory employer costs; law, not a choice — verify current rates before filing.
A38: Function | B38: Headcount | C38: Base/head | D38: Loaded/mo | E38: Rationale
A39: R&D (eng/product/design) | B39: 8 | C39: 18333 | D39: =B39*C39*(1+$B$37) -> 175996.8 | E39: Builds the product itself — protect this; it is the durable asset.
A40: S&M (quota + SE) | B40: 5 | C40: 16667 | D40: =B40*C40*(1+$B$37) -> 100002 | E40: Capacity that closes revenue; fund productive capacity, gate adds on efficiency.
A41: G&A (fin/legal/HR/IT) | B41: 4 | C41: 15000 | D41: =B41*C41*(1+$B$37) -> 72000 | E41: Runs the company; aggressive ZBB target — should grow slower than revenue.
A42: Founders & leadership | B42: 4 | C42: 12500 | D42: =B42*C42*(1+$B$37) -> 60000 | E42: Below-market founder cash comp; the core team (~88% of pre-seed is people).
A44: F. NON-LABOR OPEX (monthly)
A45: Demand generation (S&M) | B45: 40000 | C45: SAR/mo | E45: Buys pipeline; the first lever cut in a downturn (founder-led at pre-seed).
A46: Facilities (G&A) | B46: 15000 | C46: SAR/mo | E46: Somewhere to work; right-size to actual need.
...

Sheet CBS
A1: CBS — Cost Breakdown Structure (cost/month = rate × driver)
A2: Rolls up to Cost-of-Revenue / R&D / S&M / G&A and to the public-SaaS P&L lines. Every element carries its rationale.
A4: Cost element | B4: Cost/mo (SAR) | C4: Cat | D4: Public P&L | E4: Behavior | F4: Driver | G4: Split | H4: Rationale (plain English)
A5: Cloud base (compute/app) | B5: =Drivers!$B$13*Rates!$B$5 -> 5320 | C5: CoR | D5: Subscription | E5: S/V | F5: # customers | G5: sub | H5: The always-on footprint every tenant needs even at zero activity.
A6: Cloud per active partner | B6: =Drivers!$B$21*Rates!$B$6 -> 13980 | C6: CoR | D6: Subscription | E6: S/V | F6: # active partners | G6: sub | H6: Most infra scales with active partners — the true cost engine of the platform.
A7: Compute + inference / claim (capped) | B7: =Drivers!$B$25*Rates!$B$7 -> 4660 | C7: CoR | D7: Subscription | E7: V | F7: # claims | G7: sub | H7: Each claim is processed and AI-assisted; capped so AI can't erode gross margin.
A8: Evidence storage (monotonic) | B8: =Drivers!$B$28*Rates!$B$8 -> 4500 | C8: CoR | D8: Subscription | E8: V | F8: GB retained | G8: sub | H8: The evidence store only grows; without tiering this bill compounds forever.
A9: KYB/AML screening | B9: =Drivers!$B$21*Rates!$B$9 -> 4660 | C9: CoR | D9: Subscription | E9: V | F9: # active partners | G9: sub | H9: Every partner must be verified — a compliance must, not optional.
A10: e-signature / execution | B10: =Drivers!$B$25*Rates!$B$10 -> 2796 | C10: CoR | D10: Subscription | E10: V | F10: # documents | G10: sub | H10: Executing claims/contracts runs through a paid signing rail.
A11: Payout rails (Phase >=2) | B11: =Drivers!$B$27*Rates!$B$11 -> 9320 | C11: CoR | D11: Subscription | E11: V | F11: # payouts | G11: sub | H11: Moving money costs per payout — zero until the Settle gate opens.
A12: ZATCA e-invoicing | B12: =Drivers!$B$13*Rates!$B$12 -> 66.5 | C12: CoR | D12: Subscription | E12: V/S | F12: # invoices | G12: sub | H12: Saudi e-invoicing is law; cost per billed customer.
A13: Notifications | B13: =Drivers!$B$25*Rates!$B$13 -> 932 | C13: CoR | D13: Subscription | E13: V | F13: # notifications | G13: sub | H13: Every event notifies partners/customers; small but volume-scaled.
A14: Security & compliance runtime | B14: =Rates!$B$14 -> 8000 | C14: CoR | D14: Subscription | E14: F/S | F14: compliance tier | G14: sub | H14: WAF/SIEM/audit baseline; cutting it fails the enterprise/gov sale — a false economy.
A15: Residency premium (L2) | B15: =Drivers!$B$29*Rates!$B$15 -> 4500 | C15: CoR | D15: Subscription | E15: S | F15: # L2 tenants | G15: sub | H15: In-Kingdom/dedicated tenancy is the GCC wedge; it has a real, fixed cost.
A16: Support (as COGS) | B16: =Drivers!$B$32*Rates!$B$16 -> 4455 | C16: CoR | D16: Subscription | E16: S/V | F16: # tickets | G16: sub | H16: Human support is genuine COGS; self-serve deflection keeps it small.
A17: Customer Success (as COGS) | B17: =SUMPRODUCT(Drivers!$B$8:$B$12,Rates!$B$19:$B$23) -> 21400 | C17: CoR | D17: Subscription | E17: S | F17: # accounts | G17: subcs | H17: Retention labor for larger accounts; SME gets none because it must be self-serve.
A18: Implementation delivery | B18: =Drivers!$B$33*Rates!$B$27 -> 100000 | C18: CoR | D18: Services | E18: V | F18: # onboardings | G18: svc | H18: One-time delivery to get a customer live; belongs in COGS, not CAC — fenced <20% of revenue.
A19: Engineering / product / design | B19: =Rates!$D$39 -> 175996.8 | C19: R&D | D19: R&D | E19: S | F19: roadmap scope | G19: rnd | H19: Builds the product itself; protect this velocity — it is the asset.
A20: Quota sales + solution eng | B20: =Rates!$D$40 -> 100002 | C20: S&M | D20: S&M | E20: S | F20: # reps × quota | G20: sm | H20: Capacity that closes revenue; fund productive capacity, gate additions on efficiency.
A21: Demand generation | B21: =Rates!$B$45 -> 40000 | C21: S&M | D21: S&M | E21: V/F | F21: pipeline target | G21: sm | H21: Buys pipeline; the first lever to cut in a downturn.
A22: G&A labor (fin/legal/HR/IT) | B22: =Rates!$D$41 -> 72000 | C22: G&A | D22: G&A | E22: S | F22: headcount | G22: ga | H22: Runs the company; aggressive ZBB target — should grow slower than revenue.
A23: Founders & leadership | B23: =Rates!$D$42 -> 60000 | C23: G&A | D23: G&A | E23: F | F23: headcount plan | G23: ga | H23: Below-market founder cash comp; the core team.
A24: Facilities | B24: =Rates!$B$46 -> 15000 | C24: G&A | D24: G&A | E24: F/S | F24: headcount | G24: ga | H24: Office footprint; right-size to actual need.
A25: Tooling / internal SaaS | B25: =Rates!$B$47 -> 10000 | C25: G&A | D25: G&A | E25: S/V | F25: headcount | G25: ga | H25: Internal SaaS; sprawl-prone — consolidate and purge shelfware.
A26: Tax & statutory ops | B26: =Rates!$B$48 -> 8000 | C26: G&A | D26: G&A | E26: V/F | F26: net assets/spend | G26: ga | H26: Zakat/WHT/VAT provisioning; statutory, owed even pre-revenue.
A28: CATEGORY ROLL-UP (SAR / month)
A29: Cost of Revenue (CoR) | B29: =SUMIF($C$5:$C$26,"CoR",$B$5:$B$26) -> 184589.5 | H29: Everything it costs to deliver the service — the denominator of gross margin; keep under ~30 pts of revenue.
A30: Research & Development (R&D) | B30: =SUMIF($C$5:$C$26,"R&D",$B$5:$B$26) -> 175996.8 | H30: Building the product; protected pool, though capitalization policy can shift it into CoR.
A31: Sales & Marketing (S&M) | B31: =SUMIF($C$5:$C$26,"S&M",$B$5:$B$26) -> 140002 | H31: Acquiring and expanding customers; efficiency-gated by magic number and CAC payback.
A32: General & Administrative (G&A) | B32: =SUMIF($C$5:$C$26,"G&A",$B$5:$B$26) -> 165000 | H32: Running the company; the single biggest waste-attack surface for ZBB.
A33: TOTAL COST | B33: =SUM(B29:B32) -> 665588.3 | H33: All cost the business incurs this month, across every category.
A35: of which subscription CoR | B35: =SUMIF($G$5:$G$26,"sub",$B$5:$B$26)+SUMIF($G$5:$G$26,"subcs",$B$5:$B$26) -> 84589.5 | H35: The software cost base; drives the ~80–85% subscription gross margin target.
A36: of which services CoR | B36: =SUMIF($G$5:$G$26,"svc",$B$5:$B$26) -> 100000 | H36: The implementation cost base; fenced so its low margin never touches the software story.

Sheet CostToServe
A1: COST-TO-SERVE — per-tier unit economics & gross margin
A2: Subscription only (services fenced). Shared infra allocated by active-partner share. Rationale per tier at right.
A3: Shared subscription CoR ex-CS (SAR/mo): | B3: =SUMIF(CBS!$G$5:$G$26,"sub",CBS!$B$5:$B$26) -> 63189.5 | J3: The pool of shared infra cost that is spread across tiers by their partner share.
A6: Tier | B6: Customers | C6: Active ptnrs | D6: Sub rev/mo | E6: Alloc CoR | F6: Tier CS | G6: Tier CoR | H6: Contribution | I6: GM % | J6: Rationale (plain English)
A7: SME | B7: =Drivers!$B$8 -> 100 | C7: =Drivers!$B$8*Drivers!$B$16 -> 800 | D7: =Drivers!$B$8*Rates!$B$30/12 -> 10000 | E7: =IFERROR(C7/Drivers!$B$21*$B$3,0) -> 10847.983 | F7: =Drivers!$B$8*Rates!$B$19 -> 0 | G7: =E7+F7 -> 10847.983 | H7: =D7-G7 -> -847.98283 | I7: =IFERROR(H7/D7,0) -> -0.084798 | J7: Land wedge — near-zero touch; can be contribution-negative fully-allocated. That is the point: expansion, not margin.
A8: SMB | B8: =Drivers!$B$9 -> 20 | C8: =Drivers!$B$9*Drivers!$B$17 -> 800 | D8: =Drivers!$B$9*Rates!$B$31/12 -> 166666.67 | E8: =IFERROR(C8/Drivers!$B$21*$B$3,0) -> 10847.983 | F8: =Drivers!$B$9*Rates!$B$20 -> 4000 | G8: =E8+F8 -> 14847.983 | H8: =D8-G8 -> 151818.68 | I8: =IFERROR(H8/D8,0) -> 0.910912 | J8: First real margin tier; CSM-light, mostly software cost.
A9: Mid-market | B9: =Drivers!$B$10 -> 8 | C9: =Drivers!$B$10*Drivers!$B$18 -> 960 | D9: =Drivers!$B$10*Rates!$B$32/12 -> 200000 | E9: =IFERROR(C9/Drivers!$B$21*$B$3,0) -> 13017.579 | F9: =Drivers!$B$10*Rates!$B$21 -> 6400 | G9: =E9+F9 -> 19417.579 | H9: =D9-G9 -> 180582.42 | I9: =IFERROR(H9/D9,0) -> 0.902912 | J9: Finance-grade buyer; healthy contribution after a named CSM.
A10: Semi-gov | B10: =Drivers!$B$11 -> 2 | C10: =Drivers!$B$11*Drivers!$B$19 -> 600 | D10: =Drivers!$B$11*Rates!$B$33/12 -> 200000 | E10: =IFERROR(C10/Drivers!$B$21*$B$3,0) -> 8135.9871 | F10: =Drivers!$B$11*Rates!$B$22 -> 5000 | G10: =E10+F10 -> 13135.987 | H10: =D10-G10 -> 186864.01 | I10: =IFERROR(H10/D10,0) -> 0.93432 | J10: Residency premium priced to absorb the sovereignty cost and still clear the floor.
A11: Large ent | B11: =Drivers!$B$12 -> 3 | C11: =Drivers!$B$12*Drivers!$B$20 -> 1500 | D11: =Drivers!$B$12*Rates!$B$34/12 -> 225000 | E11: =IFERROR(C11/Drivers!$B$21*$B$3,0) -> 20339.968 | F11: =Drivers!$B$12*Rates!$B$23 -> 6000 | G11: =E11+F11 -> 26339.968 | H11: =D11-G11 -> 198660.03 | I11: =IFERROR(H11/D11,0) -> 0.882933 | J11: High partner volume; priced to clear the floor including its infra drag.
A12: TOTAL / BLENDED | B12: =SUM(B7:B11) -> 133 | C12: =SUM(C7:C11) -> 4660 | D12: =SUM(D7:D11) -> 801666.67 | E12: =SUM(E7:E11) -> 63189.5 | F12: =SUM(F7:F11) -> 21400 | G12: =SUM(G7:G11) -> 84589.5 | H12: =SUM(H7:H11) -> 717077.17 | I12: =IFERROR(H12/D12,0) -> 0.894483 | J12: Blended subscription gross margin (ex-services). Must clear the >=70% floor before services are even added.
A14: Checks: C12 must equal Drivers!B21 (total partners); G12 must equal CBS!B35 (total subscription CoR).

Sheet Packages
A1: DECISION PACKAGES — the zero-based unit of funding
A2: Each activity costed at Minimum-Viable / Target / Gold. Deferrability: Protect / Defer / Cut-first. Rationale = what the money buys.
A4: Package | B4: Cat | C4: Driver | D4: Behav. | E4: Deferrability | F4: MV/mo | G4: Target/mo | H4: Gold/mo | I4: Owner | J4: Outcome / rationale (why funded)
A5: B1 Core engineering (ledger/rule-engine) | B5: R&D | C5: roadmap | D5: S | E5: Protect | F5: 120000 | G5: 176000 | H5: 240000 | I5: CTO | J5: The product itself — protect velocity; it is the durable asset the company is building.
A6: A3 SOC2/ISO27001/pen-test | B6: CoR | C6: audit cadence | D6: F | E6: Protect | F6: 6000 | G6: 8000 | H6: 12000 | I6: Security | J6: Unlocks enterprise/gov trust; cutting it fails the sale — a classic false economy.
A7: D7 Statutory burden (GOSI/EOSB/levies) | B7: G&A | C7: headcount | D7: V | E7: Protect | F7: 0 | G7: 0 | H7: 0 | I7: Finance | J7: Legally owed on every employee — non-negotiable; shown for governance completeness.
A8: D8 Zakat/CIT/WHT/VAT ops | B8: G&A | C8: net assets | D8: V/F | E8: Protect | F8: 6000 | G8: 8000 | H8: 10000 | I8: Finance | J8: Statutory, owed even at a loss; under-provisioning is a compliance risk, not a saving.
A9: C1 Quota-carrying reps | B9: S&M | C9: quota capacity | D9: S | E9: Protect→Defer | F9: 60000 | G9: 100000 | H9: 160000 | I9: CRO | J9: Capacity that closes revenue; protect productive reps, gate new adds on the magic number.
A10: A6 Tier-1 support | B10: CoR | C10: tickets | D10: S/V | E10: Defer | F10: 3000 | G10: 4455 | H10: 7000 | I10: Support | J10: Keeps customers unblocked; deflect via self-serve first, then staff to residual load.
A11: A8 Implementation delivery | B11: CoR | C11: onboardings | D11: V | E11: Defer | F11: 60000 | G11: 100000 | H11: 140000 | I11: Services | J11: Gets customers live; fenced <20% of revenue and pushed to SI partners over time.
A12: A5 AI inference (capped) | B12: CoR | C12: claims | D12: V-cap | E12: Defer | F12: 3000 | G12: 4660 | H12: 6000 | I12: Product | J12: Improves attribution; hard-capped so it can never erode gross margin.
A13: C3 Paid demand generation | B13: S&M | C13: pipeline target | D13: V | E13: Cut-first | F13: 0 | G13: 40000 | H13: 90000 | I13: Marketing | J13: Buys pipeline; first to cut when cash tightens — founder-led motion covers the MV case.
A14: D5 Internal SaaS / IT | B14: G&A | C14: headcount | D14: S/V | E14: Cut-first | F14: 6000 | G14: 10000 | H14: 16000 | I14: IT | J14: Enables the team; sprawl-prone — consolidate onto fewer platforms and purge shelfware.
A15: D6 Facilities / office | B15: G&A | C15: headcount | D15: F/S | E15: Defer | F15: 10000 | G15: 15000 | H15: 25000 | I15: Ops | J15: Somewhere to work; right-size to actual headcount, expand only when full.
A16: Target-level total (illustrative) | G16: =SUM(G5:G15) -> 466115 | J16: Sum of Target service levels — the funded envelope if every package is bought at Target.

Sheet PhaseView
A1: PHASE VIEW — how the zero-base changes shape across the phase model
A2: New cost pools switch ON only at their phase gate. Current phase is driven by Drivers!B6.
A4: Current phase: | B4: =Drivers!$B$6 -> 2
A5: Payout rails active? | B5: =IF(Drivers!$B$6>=2,"ON","OFF") -> ON
A6: Settlement/% layer? | B6: =IF(Drivers!$B$6>=2,"ON (capped, fenced)","OFF") -> ON (capped, fenced)
B8: Phase 1 — Capture | C8: Phase 2 — Settle | D8: Phase 3 — Orchestrate
A9: Timeline | B9: M0–9 (all pre-seed) | C9: M9–24 | D9: M24+
A10: CoR | B10: Base cloud + first tenants; NO rails/payouts | C10: Rails/KYB/AML/e-sign/ZATCA/settlement ON; defend 70% floor | D10: Network/data cost ~100% GM; unit cost falls
A11: R&D | B11: High — build the PRM | C11: High — ledger/rule-engine/reconciliation | D11: Med — forecasting/co-sell/identity
A12: S&M | B12: Low — founder-led | C12: Med–high — reps, magic-number-gated | D12: High but efficiency-gated; expansion-led
A13: G&A | B13: Med — one-time setup + statutory | C13: Med — controls, SOC2, multi-entity | D13: Falls sub-linearly (operating leverage)
A14: Protected set | B14: Runway, statutory, security baseline | C14: + rails reliability, settlement idempotency, audit | D14: + network integrity, data governance
A15: Gate to next | B15: 100+ claims · 3–5 design partners · WAU | C15: Idempotent settlement · clean ERP recon · CFO trust | D15: —
A17: Rationale | B17: The cost base is not one shape — it is three. Funding a Phase-2 cost pool during Phase 1 (e.g. rails, settlement ops) is spend with no driver yet, and funding a Phase-1 posture at Phase 3 leaves operating leverage on the table.

Sheet Dashboard
A1: DASHBOARD — cost architecture outputs (SAR / month unless noted)
A2: All values flow from Drivers × Rates. Illustrative scale snapshot; flex the levers to explore. Rationale at right.
A4: REVENUE
A5: Subscription revenue | B5: =CostToServe!$D$12 -> 801666.67 | C5: Recurring software revenue — what the multiple is built on.
A6: Services revenue (fenced) | B6: =Drivers!$B$33*Rates!$B$26 -> 120000 | C6: One-time implementation; fenced so it doesn't dilute the software story.
A7: Total revenue | B7: =B5+B6 -> 921666.67 | C7: Top line for the period.
A9: GROSS MARGIN
A10: Subscription CoR | B10: =CostToServe!$G$12 -> 84589.5 | C10: Cost to run the software for paying customers.
A11: Services CoR | B11: =CBS!$B$18 -> 100000 | C11: Cost to deliver implementations.
A12: Total CoR | B12: =B10+B11 -> 184589.5 | C12: All cost of revenue.
A13: Gross profit | B13: =B7-B12 -> 737077.17 | C13: Revenue minus cost of revenue.
A14: Blended gross margin % | B14: =IFERROR(B13/B7,0) -> 0.799722 | C14: The number the equity multiple keys off — must clear 70%.
A15: Subscription GM % | B15: =IFERROR((B5-B10)/B5,0) -> 0.894483 | C15: Software margin; target 80–85%.
A16: Services GM % | B16: =IFERROR((B6-B11)/B6,0) -> 0.166667 | C16: Kept near-breakeven on purpose; fenced.
A17: >= 70% floor check | B17: =IF(B14>=0.7,"PASS ✅","BREACH ⚠️") -> PASS ✅ | C17: Hard guardrail from the pricing strategy; a breach means re-price or cut cost-to-serve.
A19: OPERATING EXPENSE
A20: R&D | B20: =SUMIF(CBS!$C$5:$C$26,"R&D",CBS!$B$5:$B$26) -> 175996.8 | C20: Spend on building the product.
A21: S&M | B21: =SUMIF(CBS!$C$5:$C$26,"S&M",CBS!$B$5:$B$26) -> 140002 | C21: Spend on acquiring and expanding customers.
A22: G&A | B22: =SUMIF(CBS!$C$5:$C$26,"G&A",CBS!$B$5:$B$26) -> 165000 | C22: Spend on running the company.
A23: Total OpEx | B23: =SUM(B20:B22) -> 480998.8 | C23: All operating expense below gross profit.
A25: PROFITABILITY & COST RATIOS
A26: Operating income | B26: =B13-B23 -> 256078.37 | C26: Gross profit minus OpEx.
A27: Operating margin % | B27: =IFERROR(B26/B7,0) -> 0.277843 | C27: Profitability of the period.
A28: R&D % of revenue | B28: =IFERROR(B20/B7,0) -> 0.190955 | C28: Benchmark 15–25%.
A29: S&M % of revenue | B29: =IFERROR(B21/B7,0) -> 0.151901 | C29: Benchmark 25–55% (phase-dependent).
A30: G&A % of revenue | B30: =IFERROR(B22/B7,0) -> 0.179024 | C30: Benchmark <10–15%; drive down with scale.
A32: UNIT ECONOMICS
A33: Cost to serve per customer / mo | B33: =IFERROR(B10/Drivers!$B$13,0) -> 636.01128 | C33: Unit cost — should FALL as volume grows (operating leverage).
A34: Cost per active partner / mo | B34: =IFERROR(B10/Drivers!$B$21,0) -> 18.152253 | C34: Unit cost on the main driver.
A35: Cost per claim | B35: =IFERROR(B10/Drivers!$B$25,0) -> 9.076127 | C35: Unit cost on throughput.
A36: Annualized subscription ARR | B36: =B5*12 -> 9620000 | C36: Recurring run-rate.
A38: RULE OF 40 (shell)
A39: YoY revenue growth % (input) | B39: 0.6 | C39: Your growth rate — a lever for the Rule-of-40 health check.
A40: FCF margin proxy (= operating margin) | B40: =B27 -> 0.277843 | C40: Operating margin as a stand-in for free-cash-flow margin.
A41: Rule of 40 (growth% + FCF%) | B41: =B39+B40 -> 0.877843 | C41: =IF(B41>=0.4,"PASS ✅ (>=40)","below 40") -> PASS ✅ (>=40)

Sheet Recon
A1: PHASE-1 ZERO-BASE RECONCILIATION → 2,000,000.00 SAR (canonical)
A2: Canonical values from Pre_Seed_2M_SAR_Financial_Model_Blueprint.md — DO NOT EDIT. Proves the Phase-1 zero-base ties to the round.
A4: Pillar | B4: SAR | C4: ZBC mapping & rationale
A5: Founders & basic cloud (12 mo) | B5: 829306.25 | C5: G&A (founder comp/burden) + CoR (cloud base) — the core team + the only pre-revenue CoR.
A6: Execution team — 6 hires (11 mo) | B6: 926200 | C6: R&D + S&M + CoR (support/CS) — capacity to build and prove the wedge.
A7: Setup & legal (one-time, M1) | B7: 158083.75 | C7: G&A one-time — statutory entity/visa/ZATCA setup that must happen before anything else.
A8: Emergency cash buffer | B8: 86410 | C8: Reserve — never a spend package; the liquidity floor that protects runway.
A9: TOTAL PRE-SEED ROUND | B9: =SUM(B5:B8) -> 2000000 | C9: Must equal the canonical round size exactly.
A10: Reconciliation check | B10: =IF(ROUND(B9,2)=2000000,"RECONCILED ✅","OFF BY "&TEXT(B9-2000000,"#,##0.00")) -> RECONCILED ✅
A12: Note | C12: Gross Burn = Product/R&D + GTM + CS/Implementation + COGS + G&A/Compliance.
C13: All 12 pre-seed months are Phase-1 Capture (zero-revenue). The zero-based lens does not change the total
C14: (a canonical fact) — it changes the DEFENSE: each pillar becomes an owned, ranked, service-leveled decision
C15: package with a driver. Statutory rates (GOSI/EOSB/Zakat/WHT/VAT): verify before filing.
A17: Canonical — do not edit the SAR column.
